Workbook

Sheet Plantilla
A1: ordre_zona | B1: zona | C1: ordre_parametre | D1: parametre | E1: fecha_mostra | F1: valor | G1: unitat | H1: limit_min | I1: limit_max | J1: num_muestra | K1: punto_lims_elegido | L1: tipo_punto | M1: denominacion_lims | N1: fecha_finalizacion
A2: 1 | B2: ZONA PEIRÓ | C2: 1 | D2: Microbiologia | E2: 46104.375 | F2: Correcte | G2: Correcte / Incorrecte | J2: 9155880 | K2: PEIRÓ. Xarxa Peirò A - Font de la Pica | L2: Xarxa | M2: PEIRÓ. Xarxa Peirò A - Font de la Pica | N2: 07-04-26
A3: 1 | B3: ZONA PEIRÓ | C3: 2 | D3: Organolèptic | E3: 46104.375 | F3: Correcte | G3: Correcte / Incorrecte | J3: 9155880 | K3: PEIRÓ. Xarxa Peirò A - Font de la Pica | L3: Xarxa | M3: PEIRÓ. Xarxa Peirò A - Font de la Pica | N3: 07-04-26
A4: 1 | B4: ZONA PEIRÓ | C4: 3 | D4: pH | E4: 46104.375 | F4: 7.6 | G4: U. pH. | H4: 6.9 | I4: 9.5 | J4: 9155880 | K4: PEIRÓ. Xarxa Peirò A - Font de la Pica | L4: Xarxa | M4: PEIRÓ. Xarxa Peirò A - Font de la Pica | N4: 07-04-26
A5: 1 | B5: ZONA PEIRÓ | C5: 4 | D5: Conductivitat | E5: 46104.375 | F5: 449 | G5: µS/cm | I5: 2500 | J5: 9155880 | K5: PEIRÓ. Xarxa Peirò A - Font de la Pica | L5: Xarxa | M5: PEIRÓ. Xarxa Peirò A - Font de la Pica | N5: 07-04-26
A6: 1 | B6: ZONA PEIRÓ | C6: 5 | D6: Terbolesa | E6: 46104.375 | F6: < 0.20 | G6: UNF | I6: 5 | J6: 9155880 | K6: PEIRÓ. Xarxa Peirò A - Font de la Pica | L6: Xarxa | M6: PEIRÓ. Xarxa Peirò A - Font de la Pica | N6: 07-04-26
A7: 1 | B7: ZONA PEIRÓ | C7: 6 | D7: Clor lliure | E7: 46104.375 | F7: 0.58 | G7: mg/L | I7: 1 | J7: 9155880 | K7: PEIRÓ. Xarxa Peirò A - Font de la Pica | L7: Xarxa | M7: PEIRÓ. Xarxa Peirò A - Font de la Pica | N7: 07-04-26
A8: 1 | B8: ZONA PEIRÓ | C8: 7 | D8: Duresa | E8: 46051.385 | F8: 160.3 | G8: mg/L CaCo3 | I8: 500 | J8: 8891861 | K8: PEIRÓ. Xarxa Peirò A - Font de la Pica | L8: Xarxa | M8: PEIRÓ. Xarxa Peirò A - Font de la Pica | N8: 46069
A9: 1 | B9: ZONA PEIRÓ | C9: 8 | D9: Clorurs | E9: 46051.385 | F9: 23.3 | G9: mg/L | I9: 250 | J9: 8891861 | K9: PEIRÓ. Xarxa Peirò A - Font de la Pica | L9: Xarxa | M9: PEIRÓ. Xarxa Peirò A - Font de la Pica | N9: 46069
A10: 1 | B10: ZONA PEIRÓ | C10: 9 | D10: Nitrats | E10: 46051.385 | F10: < 0.5 | G10: mg/L | I10: 50 | J10: 8891861 | K10: PEIRÓ. Xarxa Peirò A - Font de la Pica | L10: Xarxa | M10: PEIRÓ. Xarxa Peirò A - Font de la Pica | N10: 46069
A11: 2 | B11: ZONA CREUS | C11: 1 | D11: Microbiologia | E11: 46077.417 | F11: Correcte | G11: Correcte / Incorrecte | J11: 9155878 | K11: CREUS. Xarxa Creus B - Centre d'atenció primària (Mont-Roig) | L11: Xarxa | M11: CREUS. Xarxa Creus B - Centre d'atenció primària (Mont-Roig) | N11: 46084
A12: 2 | B12: ZONA CREUS | C12: 2 | D12: Organolèptic | E12: 46077.417 | F12: Correcte | G12: Correcte / Incorrecte | J12: 9155878 | K12: CREUS. Xarxa Creus B - Centre d'atenció primària (Mont-Roig) | L12: Xarxa | M12: CREUS. Xarxa Creus B - Centre d'atenció primària (Mont-Roig) | N12: 46084
A13: 2 | B13: ZONA CREUS | C13: 3 | D13: pH | E13: 46077.417 | F13: 7.8 | G13: U. pH. | H13: 6.9 | I13: 9.5 | J13: 9155878 | K13: CREUS. Xarxa Creus B - Centre d'atenció primària (Mont-Roig) | L13: Xarxa | M13: CREUS. Xarxa Creus B - Centre d'atenció primària (Mont-Roig) | N13: 46084
A14: 2 | B14: ZONA CREUS | C14: 4 | D14: Conductivitat | E14: 46077.417 | F14: 594 | G14: µS/cm | I14: 2500 | J14: 9155878 | K14: CREUS. Xarxa Creus B - Centre d'atenció primària (Mont-Roig) | L14: Xarxa | M14: CREUS. Xarxa Creus B - Centre d'atenció primària (Mont-Roig) | N14: 46084
A15: 2 | B15: ZONA CREUS | C15: 5 | D15: Terbolesa | E15: 46077.417 | F15: < 0.20 | G15: UNF | I15: 5 | J15: 9155878 | K15: CREUS. Xarxa Creus B - Centre d'atenció primària (Mont-Roig) | L15: Xarxa | M15: CREUS. Xarxa Creus B - Centre d'atenció primària (Mont-Roig) | N15: 46084
A16: 2 | B16: ZONA CREUS | C16: 6 | D16: Clor lliure | E16: 46077.417 | F16: 0.57 | G16: mg/L | I16: 1 | J16: 9155878 | K16: CREUS. Xarxa Creus B - Centre d'atenció primària (Mont-Roig) | L16: Xarxa | M16: CREUS. Xarxa Creus B - Centre d'atenció primària (Mont-Roig) | N16: 46084
A17: 2 | B17: ZONA CREUS | C17: 7 | D17: Duresa | E17: 46051.399 | F17: 234.4 | G17: mg/L CaCo3 | I17: 500 | J17: 8891862 | K17: CREUS. Xarxa Creus B - Centre d'atenció primària (Mont-Roig) | L17: Xarxa | M17: CREUS. Xarxa Creus B - Centre d'atenció primària (Mont-Roig) | N17: 46072
A18: 2 | B18: ZONA CREUS | C18: 8 | D18: Clorurs | E18: 46051.399 | F18: 36.1 | G18: mg/L CaCo3 | I18: 250 | J18: 8891862 | K18: CREUS. Xarxa Creus B - Centre d'atenció primària (Mont-Roig) | L18: Xarxa | M18: CREUS. Xarxa Creus B - Centre d'atenció primària (Mont-Roig) | N18: 46072
A19: 2 | B19: ZONA CREUS | C19: 9 | D19: Nitrats | E19: 46051.399 | F19: 36.8 | G19: mg/L CaCo3 | I19: 50 | J19: 8891862 | K19: CREUS. Xarxa Creus B - Centre d'atenció primària (Mont-Roig) | L19: Xarxa | M19: CREUS. Xarxa Creus B - Centre d'atenció primària (Mont-Roig) | N19: 46072
A20: 3 | B20: ZONA ERMITA | C20: 1 | D20: Microbiologia | E20: 46099.406 | F20: Correcte | G20: mg/L CaCo3 | J20: 9188273 | K20: ERMITA. Dipòsit Ermita | L20: Dipòsit | M20: ERMITA. Dipòsit Ermita | N20: 46113
A21: 3 | B21: ZONA ERMITA | C21: 2 | D21: Organolèptic | E21: 46099.406 | F21: Correcte | G21: mg/L CaCo3 | J21: 9188273 | K21: ERMITA. Dipòsit Ermita | L21: Dipòsit | M21: ERMITA. Dipòsit Ermita | N21: 46113
A22: 3 | B22: ZONA ERMITA | C22: 3 | D22: pH | E22: 46099.406 | F22: 7.5 | G22: mg/L CaCo3 | H22: 6.9 | I22: 9.5 | J22: 9188273 | K22: ERMITA. Dipòsit Ermita | L22: Dipòsit | M22: ERMITA. Dipòsit Ermita | N22: 46113
A23: 3 | B23: ZONA ERMITA | C23: 4 | D23: Conductivitat | E23: 46099.406 | F23: 671 | G23: mg/L CaCo3 | I23: 2500 | J23: 9188273 | K23: ERMITA. Dipòsit Ermita | L23: Dipòsit | M23: ERMITA. Dipòsit Ermita | N23: 46113
A24: 3 | B24: ZONA ERMITA | C24: 5 | D24: Terbolesa | E24: 46099.406 | F24: 1.22 | G24: mg/L CaCo3 | I24: 5 | J24: 9188273 | K24: ERMITA. Dipòsit Ermita | L24: Dipòsit | M24: ERMITA. Dipòsit Ermita | N24: 46113
A25: 3 | B25: ZONA ERMITA | C25: 6 | D25: Clor lliure | E25: 46099.406 | F25: 0.21 | G25: mg/L CaCo3 | I25: 1 | J25: 9188273 | K25: ERMITA. Dipòsit Ermita | L25: Dipòsit | M25: ERMITA. Dipòsit Ermita | N25: 46113
A26: 3 | B26: ZONA ERMITA | C26: 7 | D26: Duresa | E26: 45833 | F26: 248.7 | G26: mg/L CaCo3 | I26: 500 | J26: 8891839 | K26: ERMITA. Dipòsit Ermita | L26: Dipòsit | M26: ERMITA. Dipòsit Ermita | N26: 45861
A27: 3 | B27: ZONA ERMITA | C27: 8 | D27: Clorurs | E27: 46090 | F27: 38.81 | G27: mg/L CaCo3 | I27: 250 | J27: 8874958 | K27: ERMITA. Pou Ermita | L27: Pou | M27: ERMITA. Pou Ermita | N27: 46100
A28: 3 | B28: ZONA ERMITA | C28: 9 | D28: Nitrats | E28: 46090 | F28: < 0.50 | G28: mg/L CaCo3 | I28: 50 | J28: 8874958 | K28: ERMITA. Pou Ermita | L28: Pou | M28: ERMITA. Pou Ermita | N28: 46100
A29: 4 | B29: ZONA CLUB MONT-ROIG | C29: 1 | D29: Microbiologia | E29: 46104.358 | F29: Correcte | G29: mg/L CaCo3 | J29: 9155881 | K29: CLUB MONT-ROIG. Xarxa Club Mont-roig A - Font Parc del Club Mont-roig | L29: Xarxa | M29: CLUB MONT-ROIG. Xarxa Club Mont-roig A - Font Parc del Club Mont-roig | N29: 46113
A30: 4 | B30: ZONA CLUB MONT-ROIG | C30: 2 | D30: Organolèptic | E30: 46104.358 | F30: Correcte | G30: mg/L CaCo3 | J30: 9155881 | K30: CLUB MONT-ROIG. Xarxa Club Mont-roig A - Font Parc del Club Mont-roig | L30: Xarxa | M30: CLUB MONT-ROIG. Xarxa Club Mont-roig A - Font Parc del Club Mont-roig | N30: 46113
A31: 4 | B31: ZONA CLUB MONT-ROIG | C31: 3 | D31: pH | E31: 46104.358 | F31: 7.7 | G31: mg/L CaCo3 | H31: 6.9 | I31: 9.5 | J31: 9155881 | K31: CLUB MONT-ROIG. Xarxa Club Mont-roig A - Font Parc del Club Mont-roig | L31: Xarxa | M31: CLUB MONT-ROIG. Xarxa Club Mont-roig A - Font Parc del Club Mont-roig | N31: 46113
A32: 4 | B32: ZONA CLUB MONT-ROIG | C32: 4 | D32: Conductivitat | E32: 46104.358 | F32: 518 | G32: mg/L CaCo3 | I32: 2500 | J32: 9155881 | K32: CLUB MONT-ROIG. Xarxa Club Mont-roig A - Font Parc del Club Mont-roig | L32: Xarxa | M32: CLUB MONT-ROIG. Xarxa Club Mont-roig A - Font Parc del Club Mont-roig | N32: 46113
A33: 4 | B33: ZONA CLUB MONT-ROIG | C33: 5 | D33: Terbolesa | E33: 46104.358 | F33: < 0.20 | G33: mg/L CaCo3 | I33: 5 | J33: 9155881 | K33: CLUB MONT-ROIG. Xarxa Club Mont-roig A - Font Parc del Club Mont-roig | L33: Xarxa | M33: CLUB MONT-ROIG. Xarxa Club Mont-roig A - Font Parc del Club Mont-roig | N33: 46113
A34: 4 | B34: ZONA CLUB MONT-ROIG | C34: 6 | D34: Clor lliure | E34: 46104.358 | F34: 0.23 | G34: mg/L CaCo3 | I34: 1 | J34: 9155881 | K34: CLUB MONT-ROIG. Xarxa Club Mont-roig A - Font Parc del Club Mont-roig | L34: Xarxa | M34: CLUB MONT-ROIG. Xarxa Club Mont-roig A - Font Parc del Club Mont-roig | N34: 46113
A35: 4 | B35: ZONA CLUB MONT-ROIG | C35: 7 | D35: Duresa | E35: 46052.375 | F35: 220.9 | G35: mg/L CaCo3 | I35: 500 | J35: 8891863 | K35: CLUB MONT-ROIG. Xarxa Club Mont-roig A - Font Parc del Club Mont-roig | L35: Xarxa | M35: CLUB MONT-ROIG. Xarxa Club Mont-roig A - Font Parc del Club Mont-roig | N35: 46072
A36: 4 | B36: ZONA CLUB MONT-ROIG | C36: 8 | D36: Clorurs | E36: 46052.375 | F36: 34.6 | G36: mg/L CaCo3 | I36: 250 | J36: 8891863 | K36: CLUB MONT-ROIG. Xarxa Club Mont-roig A - Font Parc del Club Mont-roig | L36: Xarxa | M36: CLUB MONT-ROIG. Xarxa Club Mont-roig A - Font Parc del Club Mont-roig | N36: 46072
A37: 4 | B37: ZONA CLUB MONT-ROIG | C37: 9 | D37: Nitrats | E37: 46052.375 | F37: 37.7 | G37: mg/L CaCo3 | I37: 50 | J37: 8891863 | K37: CLUB MONT-ROIG. Xarxa Club Mont-roig A - Font Parc del Club Mont-roig | L37: Xarxa | M37: CLUB MONT-ROIG. Xarxa Club Mont-roig A - Font Parc del Club Mont-roig | N37: 46072
A38: 5 | B38: ZONA BADIA-MAINOU-JARDINS-BALNEARI | C38: 1 | D38: Microbiologia | E38: 46106.396 | F38: Correcte | G38: mg/L CaCo3 | J38: 9155882 | K38: MONT-ROIG BADIA-MAINOU-JARDINS PARADÍS-RUSTICAL BALNEARI. Xarxa Badia Rustical Balneari B- Font | L38: Xarxa | M38: MONT-ROIG BADIA-MAINOU-JARDINS PARADÍS-RUSTICAL BALNEARI. Xarxa Badia Rustical Balneari B- Font | N38: 46119
A39: 5 | B39: ZONA BADIA-MAINOU-JARDINS-BALNEARI | C39: 2 | D39: Organolèptic | E39: 46106.396 | F39: Correcte | G39: mg/L CaCo3 | J39: 9155882 | K39: MONT-ROIG BADIA-MAINOU-JARDINS PARADÍS-RUSTICAL BALNEARI. Xarxa Badia Rustical Balneari B- Font | L39: Xarxa | M39: MONT-ROIG BADIA-MAINOU-JARDINS PARADÍS-RUSTICAL BALNEARI. Xarxa Badia Rustical Balneari B- Font | N39: 46119
A40: 5 | B40: ZONA BADIA-MAINOU-JARDINS-BALNEARI | C40: 3 | D40: pH | E40: 46106.396 | F40: 7.9 | G40: mg/L CaCo3 | H40: 6.9 | I40: 9.5 | J40: 9155882 | K40: MONT-ROIG BADIA-MAINOU-JARDINS PARADÍS-RUSTICAL BALNEARI. Xarxa Badia Rustical Balneari B- Font | L40: Xarxa | M40: MONT-ROIG BADIA-MAINOU-JARDINS PARADÍS-RUSTICAL BALNEARI. Xarxa Badia Rustical Balneari B- Font | N40: 46119
...

Sheet resultats 15042026
A2: zona | B2: data_mostra | C2: parametre | D2: valor | E2: unitat | F2: limit_min | G2: limit_max
A3: =Plantilla!B2 -> ZONA PEIRÓ | B3: =Plantilla!E2 -> 46104.375 | C3: =Plantilla!D2 -> Microbiologia | D3: =Plantilla!F2 -> Correcte | E3: =Plantilla!G2 -> Correcte / Incorrecte
A4: =Plantilla!B3 -> ZONA PEIRÓ | B4: =Plantilla!E3 -> 46104.375 | C4: =Plantilla!D3 -> Organolèptic | D4: =Plantilla!F3 -> Correcte | E4: =Plantilla!G3 -> Correcte / Incorrecte
A5: =Plantilla!B4 -> ZONA PEIRÓ | B5: =Plantilla!E4 -> 46104.375 | C5: =Plantilla!D4 -> pH | D5: =Plantilla!F4 -> 7.6 | E5: =Plantilla!G4 -> U. pH. | F5: =Plantilla!H4 -> 6.9 | G5: =Plantilla!I4 -> 9.5
A6: =Plantilla!B5 -> ZONA PEIRÓ | B6: =Plantilla!E5 -> 46104.375 | C6: =Plantilla!D5 -> Conductivitat | D6: =Plantilla!F5 -> 449 | E6: =Plantilla!G5 -> µS/cm | G6: =Plantilla!I5 -> 2500
A7: =Plantilla!B6 -> ZONA PEIRÓ | B7: =Plantilla!E6 -> 46104.375 | C7: =Plantilla!D6 -> Terbolesa | D7: =Plantilla!F6 -> < 0.20 | E7: =Plantilla!G6 -> UNF | G7: =Plantilla!I6 -> 5
A8: =Plantilla!B7 -> ZONA PEIRÓ | B8: =Plantilla!E7 -> 46104.375 | C8: =Plantilla!D7 -> Clor lliure | D8: =Plantilla!F7 -> 0.58 | E8: =Plantilla!G7 -> mg/L | G8: =Plantilla!I7 -> 1
A9: =Plantilla!B8 -> ZONA PEIRÓ | B9: =Plantilla!E8 -> 46051.385 | C9: =Plantilla!D8 -> Duresa | D9: =Plantilla!F8 -> 160.3 | E9: =Plantilla!G8 -> mg/L CaCo3 | G9: =Plantilla!I8 -> 500
A10: =Plantilla!B9 -> ZONA PEIRÓ | B10: =Plantilla!E9 -> 46051.385 | C10: =Plantilla!D9 -> Clorurs | D10: =Plantilla!F9 -> 23.3 | E10: =Plantilla!G9 -> mg/L | G10: =Plantilla!I9 -> 250
A11: =Plantilla!B10 -> ZONA PEIRÓ | B11: =Plantilla!E10 -> 46051.385 | C11: =Plantilla!D10 -> Nitrats | D11: =Plantilla!F10 -> < 0.5 | E11: =Plantilla!G10 -> mg/L | G11: =Plantilla!I10 -> 50
A12: =Plantilla!B11 -> ZONA CREUS | B12: =Plantilla!E11 -> 46077.417 | C12: =Plantilla!D11 -> Microbiologia | D12: =Plantilla!F11 -> Correcte | E12: =Plantilla!G11 -> Correcte / Incorrecte
A13: =Plantilla!B12 -> ZONA CREUS | B13: =Plantilla!E12 -> 46077.417 | C13: =Plantilla!D12 -> Organolèptic | D13: =Plantilla!F12 -> Correcte | E13: =Plantilla!G12 -> Correcte / Incorrecte
A14: =Plantilla!B13 -> ZONA CREUS | B14: =Plantilla!E13 -> 46077.417 | C14: =Plantilla!D13 -> pH | D14: =Plantilla!F13 -> 7.8 | E14: =Plantilla!G13 -> U. pH. | F14: =Plantilla!H13 -> 6.9 | G14: =Plantilla!I13 -> 9.5
A15: =Plantilla!B14 -> ZONA CREUS | B15: =Plantilla!E14 -> 46077.417 | C15: =Plantilla!D14 -> Conductivitat | D15: =Plantilla!F14 -> 594 | E15: =Plantilla!G14 -> µS/cm | G15: =Plantilla!I14 -> 2500
A16: =Plantilla!B15 -> ZONA CREUS | B16: =Plantilla!E15 -> 46077.417 | C16: =Plantilla!D15 -> Terbolesa | D16: =Plantilla!F15 -> < 0.20 | E16: =Plantilla!G15 -> UNF | G16: =Plantilla!I15 -> 5
A17: =Plantilla!B16 -> ZONA CREUS | B17: =Plantilla!E16 -> 46077.417 | C17: =Plantilla!D16 -> Clor lliure | D17: =Plantilla!F16 -> 0.57 | E17: =Plantilla!G16 -> mg/L | G17: =Plantilla!I16 -> 1
A18: =Plantilla!B17 -> ZONA CREUS | B18: =Plantilla!E17 -> 46051.399 | C18: =Plantilla!D17 -> Duresa | D18: =Plantilla!F17 -> 234.4 | E18: =Plantilla!G17 -> mg/L CaCo3 | G18: =Plantilla!I17 -> 500
A19: =Plantilla!B18 -> ZONA CREUS | B19: =Plantilla!E18 -> 46051.399 | C19: =Plantilla!D18 -> Clorurs | D19: =Plantilla!F18 -> 36.1 | E19: =Plantilla!G18 -> mg/L CaCo3 | G19: =Plantilla!I18 -> 250
A20: =Plantilla!B19 -> ZONA CREUS | B20: =Plantilla!E19 -> 46051.399 | C20: =Plantilla!D19 -> Nitrats | D20: =Plantilla!F19 -> 36.8 | E20: =Plantilla!G19 -> mg/L CaCo3 | G20: =Plantilla!I19 -> 50
A21: =Plantilla!B20 -> ZONA ERMITA | B21: =Plantilla!E20 -> 46099.406 | C21: =Plantilla!D20 -> Microbiologia | D21: =Plantilla!F20 -> Correcte | E21: =Plantilla!G20 -> mg/L CaCo3
A22: =Plantilla!B21 -> ZONA ERMITA | B22: =Plantilla!E21 -> 46099.406 | C22: =Plantilla!D21 -> Organolèptic | D22: =Plantilla!F21 -> Correcte | E22: =Plantilla!G21 -> mg/L CaCo3
A23: =Plantilla!B22 -> ZONA ERMITA | B23: =Plantilla!E22 -> 46099.406 | C23: =Plantilla!D22 -> pH | D23: =Plantilla!F22 -> 7.5 | E23: =Plantilla!G22 -> mg/L CaCo3 | F23: =Plantilla!H22 -> 6.9 | G23: =Plantilla!I22 -> 9.5
A24: =Plantilla!B23 -> ZONA ERMITA | B24: =Plantilla!E23 -> 46099.406 | C24: =Plantilla!D23 -> Conductivitat | D24: =Plantilla!F23 -> 671 | E24: =Plantilla!G23 -> mg/L CaCo3 | G24: =Plantilla!I23 -> 2500
A25: =Plantilla!B24 -> ZONA ERMITA | B25: =Plantilla!E24 -> 46099.406 | C25: =Plantilla!D24 -> Terbolesa | D25: =Plantilla!F24 -> 1.22 | E25: =Plantilla!G24 -> mg/L CaCo3 | G25: =Plantilla!I24 -> 5
A26: =Plantilla!B25 -> ZONA ERMITA | B26: =Plantilla!E25 -> 46099.406 | C26: =Plantilla!D25 -> Clor lliure | D26: =Plantilla!F25 -> 0.21 | E26: =Plantilla!G25 -> mg/L CaCo3 | G26: =Plantilla!I25 -> 1
A27: =Plantilla!B26 -> ZONA ERMITA | B27: =Plantilla!E26 -> 45833 | C27: =Plantilla!D26 -> Duresa | D27: =Plantilla!F26 -> 248.7 | E27: =Plantilla!G26 -> mg/L CaCo3 | G27: =Plantilla!I26 -> 500
A28: =Plantilla!B27 -> ZONA ERMITA | B28: =Plantilla!E27 -> 46090 | C28: =Plantilla!D27 -> Clorurs | D28: =Plantilla!F27 -> 38.81 | E28: =Plantilla!G27 -> mg/L CaCo3 | G28: =Plantilla!I27 -> 250
A29: =Plantilla!B28 -> ZONA ERMITA | B29: =Plantilla!E28 -> 46090 | C29: =Plantilla!D28 -> Nitrats | D29: =Plantilla!F28 -> < 0.50 | E29: =Plantilla!G28 -> mg/L CaCo3 | G29: =Plantilla!I28 -> 50
A30: =Plantilla!B29 -> ZONA CLUB MONT-ROIG | B30: =Plantilla!E29 -> 46104.358 | C30: =Plantilla!D29 -> Microbiologia | D30: =Plantilla!F29 -> Correcte | E30: =Plantilla!G29 -> mg/L CaCo3
A31: =Plantilla!B30 -> ZONA CLUB MONT-ROIG | B31: =Plantilla!E30 -> 46104.358 | C31: =Plantilla!D30 -> Organolèptic | D31: =Plantilla!F30 -> Correcte | E31: =Plantilla!G30 -> mg/L CaCo3
A32: =Plantilla!B31 -> ZONA CLUB MONT-ROIG | B32: =Plantilla!E31 -> 46104.358 | C32: =Plantilla!D31 -> pH | D32: =Plantilla!F31 -> 7.7 | E32: =Plantilla!G31 -> mg/L CaCo3 | F32: =Plantilla!H31 -> 6.9 | G32: =Plantilla!I31 -> 9.5
A33: =Plantilla!B32 -> ZONA CLUB MONT-ROIG | B33: =Plantilla!E32 -> 46104.358 | C33: =Plantilla!D32 -> Conductivitat | D33: =Plantilla!F32 -> 518 | E33: =Plantilla!G32 -> mg/L CaCo3 | G33: =Plantilla!I32 -> 2500
A34: =Plantilla!B33 -> ZONA CLUB MONT-ROIG | B34: =Plantilla!E33 -> 46104.358 | C34: =Plantilla!D33 -> Terbolesa | D34: =Plantilla!F33 -> < 0.20 | E34: =Plantilla!G33 -> mg/L CaCo3 | G34: =Plantilla!I33 -> 5
A35: =Plantilla!B34 -> ZONA CLUB MONT-ROIG | B35: =Plantilla!E34 -> 46104.358 | C35: =Plantilla!D34 -> Clor lliure | D35: =Plantilla!F34 -> 0.23 | E35: =Plantilla!G34 -> mg/L CaCo3 | G35: =Plantilla!I34 -> 1
A36: =Plantilla!B35 -> ZONA CLUB MONT-ROIG | B36: =Plantilla!E35 -> 46052.375 | C36: =Plantilla!D35 -> Duresa | D36: =Plantilla!F35 -> 220.9 | E36: =Plantilla!G35 -> mg/L CaCo3 | G36: =Plantilla!I35 -> 500
A37: =Plantilla!B36 -> ZONA CLUB MONT-ROIG | B37: =Plantilla!E36 -> 46052.375 | C37: =Plantilla!D36 -> Clorurs | D37: =Plantilla!F36 -> 34.6 | E37: =Plantilla!G36 -> mg/L CaCo3 | G37: =Plantilla!I36 -> 250
A38: =Plantilla!B37 -> ZONA CLUB MONT-ROIG | B38: =Plantilla!E37 -> 46052.375 | C38: =Plantilla!D37 -> Nitrats | D38: =Plantilla!F37 -> 37.7 | E38: =Plantilla!G37 -> mg/L CaCo3 | G38: =Plantilla!I37 -> 50
A39: =Plantilla!B38 -> ZONA BADIA-MAINOU-JARDINS-BALNEARI | B39: =Plantilla!E38 -> 46106.396 | C39: =Plantilla!D38 -> Microbiologia | D39: =Plantilla!F38 -> Correcte | E39: =Plantilla!G38 -> mg/L CaCo3
A40: =Plantilla!B39 -> ZONA BADIA-MAINOU-JARDINS-BALNEARI | B40: =Plantilla!E39 -> 46106.396 | C40: =Plantilla!D39 -> Organolèptic | D40: =Plantilla!F39 -> Correcte | E40: =Plantilla!G39 -> mg/L CaCo3
A41: =Plantilla!B40 -> ZONA BADIA-MAINOU-JARDINS-BALNEARI | B41: =Plantilla!E40 -> 46106.396 | C41: =Plantilla!D40 -> pH | D41: =Plantilla!F40 -> 7.9 | E41: =Plantilla!G40 -> mg/L CaCo3 | F41: =Plantilla!H40 -> 6.9 | G41: =Plantilla!I40 -> 9.5
...

Sheet Catalogos
A1: Zona oficial | B1: Paràmetre | C1: Tipus punt | D1: Ordre prioritat | F1: Paràmetre | G1: Unitat suggerida | H1: Límit mínim | I1: Límit màxim
A2: ZONA PEIRÓ | B2: Microbiologia | C2: Xarxa | D2: 1 | F2: Microbiologia | G2: Correcte / Incorrecte
A3: ZONA CREUS | B3: Organolèptic | C3: Dipòsit | D3: 2 | F3: Organolèptic | G3: Correcte / Incorrecte
A4: ZONA ERMITA | B4: pH | C4: Pou | D4: 3 | F4: pH | G4: unit pH | H4: 6.9 | I4: 9.5
A5: ZONA CLUB MONT-ROIG | B5: Conductivitat | C5: Altre | D5: 4 | F5: Conductivitat | G5: µS/cm | I5: 2500
A6: ZONA BADIA-MAINOU-JARDINS-BALNEARI | B6: Terbolesa | F6: Terbolesa | G6: NTU | I6: 5
A7: ZONA SANT MIQUEL-RUSTICAL | B7: Clor lliure | F7: Clor lliure | G7: mg/L | I7: 1
A8: ZONA MASOS-GUARDAMAR-RIBERA | B8: Duresa | F8: Duresa | G8: mg/L CaCo3 | I8: 500
A9: ZONA PINS DE MIRAMAR | B9: Clorurs | F9: Clorurs | G9: mg/L | I9: 250
A10: ZONA SOLEMIO | B10: Nitrats | F10: Nitrats | G10: mg/L | I10: 50
A11: ZONA MIAMI PLATJA
A12: ZONA COSTA ZÈFIR
A13: ZONA ROMA
A14: ZONA RANXOS
A15: ZONA BONMONT
A16: ZONA VIA MARINA
